Workbook

Sheet 안내
A1: 중대범죄수사청 조직·정원·법령 정리표
A2: 기준일 | B2: 2026. 10. 2. (중수청 개청일)
A3: 근거 자료 | B3: 중수청법(법률 제21491호), 같은 법 시행령(대통령령 제36596호), 「중대범죄수사청과 그 소속기관 직제」(대통령령 제36602호), 같은 직제 시행규칙(행정안전부령 제643호), 중대범죄수사청 특례임용 임용희망 신청 공고(2026. 8. 7.) 별첨 1·2
A5: 시트 구성
A6: 청별 요약 | B6: 청별 직급별 정원 합계. ‘부서별 정원’ 시트에서 자동 합산되므로 직접 고치지 마세요.
A7: 부서별 정원 | B7: 공고 별첨2 정원표(4급 비보직~9급). 파란 숫자·노란 칸을 고치면 합계가 자동으로 바뀝니다.
A8: 조직·업무 | B8: 부서 180개의 보직 계급, 근거 조문, 분장 업무, 사건 범위. 자유롭게 고치거나 행을 추가하세요.
A9: 관할구역 | B9: 청별 위치와 관할구역. ‘확인 필요’ 열을 원문 확인 후 갱신하세요.
A10: 법령 목록 | B10: 확인해야 할 법령. ‘확인’ 열에 ○를 넣으면 진행률이 계산됩니다.
A11: 내 보관함 | B11: 흩어진 법령·훈령·내부지침을 모아 두는 표. 2행은 예시이니 지워도 됩니다.
A12: 타기관 충원 | B12: 직제 §36④에 따라 다른 기관 소속으로 충원하는 정원.
A14: 편집 규칙 | B14: 파란 글씨 = 직접 입력한 값(수정 대상) / 검정 글씨 = 수식(자동 계산) / 노란 배경 = 입력 칸
A15: 주의 | B15: 관할구역은 직제 별표 1 원문이 자료에 없어 ‘고등법원 관할구역에 대응’ 원칙으로 정리했습니다. 과별 정원은 공고되지 않아 국(신청단위) 단위로만 있습니다. 업무 문구는 조문 요약이므로 인용 시 원문을 확인하세요.

Sheet 청별 요약
A1: 청 | B1: 기관명 | C1: 4급(비보직) | D1: 5급 | E1: 6급 | F1: 7급 | G1: 8급 | H1: 9급 | I1: 수사관 계 | J1: 관리운영 | K1: 공고 계(검증) | L1: 차이
A2: 본청 | B2: 중대범죄수사청 | C2: =SUMIFS('부서별 정원'!E$2:E$45,'부서별 정원'!$A$2:$A$45,$A2) | D2: =SUMIFS('부서별 정원'!F$2:F$45,'부서별 정원'!$A$2:$A$45,$A2) | E2: =SUMIFS('부서별 정원'!G$2:G$45,'부서별 정원'!$A$2:$A$45,$A2) | F2: =SUMIFS('부서별 정원'!H$2:H$45,'부서별 정원'!$A$2:$A$45,$A2) | G2: =SUMIFS('부서별 정원'!I$2:I$45,'부서별 정원'!$A$2:$A$45,$A2) | H2: =SUMIFS('부서별 정원'!J$2:J$45,'부서별 정원'!$A$2:$A$45,$A2) | I2: =SUM(C2:H2) | J2: =SUMIFS('부서별 정원'!L$2:L$45,'부서별 정원'!$A$2:$A$45,$A2) | K2: 300 | L2: =I2-K2
A3: 서울 | B3: 서울지방중대범죄수사청 | C3: =SUMIFS('부서별 정원'!E$2:E$45,'부서별 정원'!$A$2:$A$45,$A3) | D3: =SUMIFS('부서별 정원'!F$2:F$45,'부서별 정원'!$A$2:$A$45,$A3) | E3: =SUMIFS('부서별 정원'!G$2:G$45,'부서별 정원'!$A$2:$A$45,$A3) | F3: =SUMIFS('부서별 정원'!H$2:H$45,'부서별 정원'!$A$2:$A$45,$A3) | G3: =SUMIFS('부서별 정원'!I$2:I$45,'부서별 정원'!$A$2:$A$45,$A3) | H3: =SUMIFS('부서별 정원'!J$2:J$45,'부서별 정원'!$A$2:$A$45,$A3) | I3: =SUM(C3:H3) | J3: =SUMIFS('부서별 정원'!L$2:L$45,'부서별 정원'!$A$2:$A$45,$A3) | K3: 947 | L3: =I3-K3
A4: 수원 | B4: 수원지방중대범죄수사청 | C4: =SUMIFS('부서별 정원'!E$2:E$45,'부서별 정원'!$A$2:$A$45,$A4) | D4: =SUMIFS('부서별 정원'!F$2:F$45,'부서별 정원'!$A$2:$A$45,$A4) | E4: =SUMIFS('부서별 정원'!G$2:G$45,'부서별 정원'!$A$2:$A$45,$A4) | F4: =SUMIFS('부서별 정원'!H$2:H$45,'부서별 정원'!$A$2:$A$45,$A4) | G4: =SUMIFS('부서별 정원'!I$2:I$45,'부서별 정원'!$A$2:$A$45,$A4) | H4: =SUMIFS('부서별 정원'!J$2:J$45,'부서별 정원'!$A$2:$A$45,$A4) | I4: =SUM(C4:H4) | J4: =SUMIFS('부서별 정원'!L$2:L$45,'부서별 정원'!$A$2:$A$45,$A4) | K4: 275 | L4: =I4-K4
A5: 대전 | B5: 대전지방중대범죄수사청 | C5: =SUMIFS('부서별 정원'!E$2:E$45,'부서별 정원'!$A$2:$A$45,$A5) | D5: =SUMIFS('부서별 정원'!F$2:F$45,'부서별 정원'!$A$2:$A$45,$A5) | E5: =SUMIFS('부서별 정원'!G$2:G$45,'부서별 정원'!$A$2:$A$45,$A5) | F5: =SUMIFS('부서별 정원'!H$2:H$45,'부서별 정원'!$A$2:$A$45,$A5) | G5: =SUMIFS('부서별 정원'!I$2:I$45,'부서별 정원'!$A$2:$A$45,$A5) | H5: =SUMIFS('부서별 정원'!J$2:J$45,'부서별 정원'!$A$2:$A$45,$A5) | I5: =SUM(C5:H5) | J5: =SUMIFS('부서별 정원'!L$2:L$45,'부서별 정원'!$A$2:$A$45,$A5) | K5: 210 | L5: =I5-K5
A6: 대구 | B6: 대구지방중대범죄수사청 | C6: =SUMIFS('부서별 정원'!E$2:E$45,'부서별 정원'!$A$2:$A$45,$A6) | D6: =SUMIFS('부서별 정원'!F$2:F$45,'부서별 정원'!$A$2:$A$45,$A6) | E6: =SUMIFS('부서별 정원'!G$2:G$45,'부서별 정원'!$A$2:$A$45,$A6) | F6: =SUMIFS('부서별 정원'!H$2:H$45,'부서별 정원'!$A$2:$A$45,$A6) | G6: =SUMIFS('부서별 정원'!I$2:I$45,'부서별 정원'!$A$2:$A$45,$A6) | H6: =SUMIFS('부서별 정원'!J$2:J$45,'부서별 정원'!$A$2:$A$45,$A6) | I6: =SUM(C6:H6) | J6: =SUMIFS('부서별 정원'!L$2:L$45,'부서별 정원'!$A$2:$A$45,$A6) | K6: 182 | L6: =I6-K6
A7: 부산 | B7: 부산지방중대범죄수사청 | C7: =SUMIFS('부서별 정원'!E$2:E$45,'부서별 정원'!$A$2:$A$45,$A7) | D7: =SUMIFS('부서별 정원'!F$2:F$45,'부서별 정원'!$A$2:$A$45,$A7) | E7: =SUMIFS('부서별 정원'!G$2:G$45,'부서별 정원'!$A$2:$A$45,$A7) | F7: =SUMIFS('부서별 정원'!H$2:H$45,'부서별 정원'!$A$2:$A$45,$A7) | G7: =SUMIFS('부서별 정원'!I$2:I$45,'부서별 정원'!$A$2:$A$45,$A7) | H7: =SUMIFS('부서별 정원'!J$2:J$45,'부서별 정원'!$A$2:$A$45,$A7) | I7: =SUM(C7:H7) | J7: =SUMIFS('부서별 정원'!L$2:L$45,'부서별 정원'!$A$2:$A$45,$A7) | K7: 276 | L7: =I7-K7
A8: 광주 | B8: 광주지방중대범죄수사청 | C8: =SUMIFS('부서별 정원'!E$2:E$45,'부서별 정원'!$A$2:$A$45,$A8) | D8: =SUMIFS('부서별 정원'!F$2:F$45,'부서별 정원'!$A$2:$A$45,$A8) | E8: =SUMIFS('부서별 정원'!G$2:G$45,'부서별 정원'!$A$2:$A$45,$A8) | F8: =SUMIFS('부서별 정원'!H$2:H$45,'부서별 정원'!$A$2:$A$45,$A8) | G8: =SUMIFS('부서별 정원'!I$2:I$45,'부서별 정원'!$A$2:$A$45,$A8) | H8: =SUMIFS('부서별 정원'!J$2:J$45,'부서별 정원'!$A$2:$A$45,$A8) | I8: =SUM(C8:H8) | J8: =SUMIFS('부서별 정원'!L$2:L$45,'부서별 정원'!$A$2:$A$45,$A8) | K8: 198 | L8: =I8-K8
A9: 합계 | B9: 본청 + 6개 지방청 | C9: =SUM(C2:C8) | D9: =SUM(D2:D8) | E9: =SUM(E2:E8) | F9: =SUM(F2:F8) | G9: =SUM(G2:G8) | H9: =SUM(H2:H8) | I9: =SUM(I2:I8) | J9: =SUM(J2:J8) | ... L9: =SUM(L2:L8)
A11: 수사관 계·관리운영은 ‘부서별 정원’ 시트에서 자동 합산됩니다. ‘공고 계’는 공고 별첨2 각 청 ‘계’ 행 값이며, ‘차이’가 ✓이면 일치합니다. 국·과장 보직자(1~4급 보직)는 이 표에 포함되지 않습니다.

Sheet 부서별 정원
A1: 청 | B1: 신청단위(부서) | C1: 하부 부서 | D1: 보직 | E1: 4급(비보직) | F1: 5급 | G1: 6급 | H1: 7급 | I1: 8급 | J1: 9급 | K1: 수사관 계 | L1: 관리운영 | M1: 일반직 | N1: 비고
A2: 본청 | B2: 부속실 | C2: 중대범죄수사청장, 차장 | E2: 0 | F2: 1 | G2: 2 | H2: 0 | I2: 0 | J2: 0 | K2: =SUM(E2:J2) | L2: 3 | N2: 청장·차장 부속
A3: 본청 | B3: 감찰관 | C3: 감찰담당관, 감사담당관, 인권·양성평등담당관 | D3: 2급 | E3: 3 | F3: 5 | G3: 13 | H3: 12 | I3: 4 | J3: 0 | K3: =SUM(E3:J3) | L3: 1 | M3: 인권·양성평등담당관: 전문경력관 나급(1)
A4: 본청 | B4: 대변인 | C4: 공보담당관 | D4: 2급 | E4: 1 | F4: 1 | G4: 1 | H4: 3 | I4: 3 | J4: 0 | K4: =SUM(E4:J4) | L4: 1 | M4: 공보담당관: 전문경력관 나급(1)
A5: 본청 | B5: 기획조정관 | C5: 기획재정담당관, 국제협력담당관, 정보통신담당관, 비상안전담당관 | D5: 2급 | E5: 3 | F5: 4 | G5: 10 | H5: 9 | I5: 5 | J5: 0 | K5: =SUM(E5:J5) | L5: 1 | M5: 정보통신담당관: 전산·방송통신 5급(2)·6급(4)·7급(4)·8급(2)·9급(1) / 비상안전담당관실: 방호 8급(3)·9급(4)
A6: 본청 | B6: 인사정책기획관 | C6: 인사담당관, 수사정책담당관 | D6: 2급 | E6: 12 | F6: 25 | G6: 7 | H6: 5 | I6: 3 | J6: 0 | K6: =SUM(E6:J6) | L6: 1 | M6: 인사담당관: 전산·방송통신 7급(1)·8급(2)
A7: 본청 | B7: 수사정보관 | C7: 수사정보1담당관, 수사정보2담당관 | D7: 2급 | E7: 2 | F7: 3 | G7: 8 | H7: 8 | I7: 2 | J7: 0 | K7: =SUM(E7:J7) | L7: 1
A8: 본청 | B8: 경제범죄수사국 | C8: 경제범죄수사과, 금융범죄수사과, 반독점수사과, 범죄수익수사과 | D8: 2급 | E8: 4 | F8: 7 | G8: 11 | H8: 8 | I8: 4 | J8: 0 | K8: =SUM(E8:J8) | L8: 1
A9: 본청 | B9: 반부패수사국 | C9: 반부패수사과, 마약수사과, 공공사회안전수사과, 자금추적·회계분석과 | D9: 2급 | E9: 6 | F9: 10 | G9: 17 | H9: 15 | I9: 5 | J9: 0 | K9: =SUM(E9:J9) | L9: 1 | M9: 공공사회안전수사과: 심리연구사(2)
A10: 본청 | B10: 과학수사국 | C10: 사이버기술수사과, 디지털수사과, AI가상자산분석과 | D10: 2급 | E10: 0 | F10: 5 | G10: 12 | H10: 11 | I10: 16 | J10: 0 | K10: =SUM(E10:J10) | L10: 1 | M10: 사이버기술수사과: 전산·방송통신 5급(1)·6급(1)·7급(4)·9급(1) / 디지털수사과: 전산·방송통신 5급(1)·6급(1)·8급(2)
A11: 본청 | B11: 운영지원과 | D11: 4급 | E11: 0 | F11: 3 | G11: 3 | H11: 4 | I11: 4 | J11: 0 | K11: =SUM(E11:J11) | L11: 0 | M11: 시설·공업 7급(2) / 운전 7급(1)·8급(3)·9급(4) / 기록연구사(1)
A12: 서울 | B12: 부속실 | C12: 서울지방중대범죄수사청장, 1차장, 2차장, 3차장 | E12: 0 | F12: 0 | G12: 4 | H12: 0 | I12: 0 | J12: 0 | K12: =SUM(E12:J12) | L12: 5 | N12: 청장·차장 부속
A13: 서울 | B13: 담당관(4개) | C13: 수사심의담당관, 인권보호담당관, 기획공보담당관, 수사정보담당관 | D13: 4급 | E13: 4 | F13: 6 | G13: 16 | H13: 17 | I13: 7 | J13: 5 | K13: =SUM(E13:J13) | L13: 0 | N13: 담당관 4개 합계
A14: 서울 | B14: 사무국 | C14: 총무과, 사건과, 증거기록과, 수사지원과, 과학수사지원과 | D14: 3급 | E14: 3 | F14: 8 | G14: 19 | H14: 35 | I14: 43 | J14: 27 | K14: =SUM(E14:J14) | L14: 1 | M14: 총무과: 전산·방송통신 6급(1)·7급(1)·8급(1)·9급(2) / 시설 7급(1)·8급(1)·9급(1) / 운전 7급(1)·8급(4)·9급(9) / 방호 8급(2)·9급(2) / 기록연구사(1)
A15: 서울 | B15: 경제범죄수사국 | C15: 중대경제범죄수사1과, 중대경제범죄수사2과, 조세범죄수사과, 국제경제범죄수사과, 범죄수익수사과 | D15: 3급 | E15: 5 | F15: 30 | G15: 40 | H15: 50 | I15: 35 | J15: 15 | K15: =SUM(E15:J15) | L15: 1
A16: 서울 | B16: 금융범죄수사국 | C16: 금융범죄수사1과, 금융범죄수사2과, 금융범죄합동수사과, 가상자산합동수사과 | D16: 3급 | E16: 4 | F16: 24 | G16: 27 | H16: 34 | I16: 24 | J16: 9 | K16: =SUM(E16:J16) | L16: 1 | M16: 가상자산합동수사과: 전산·방송통신 6급(3)·7급(5)·8급(5)·9급(3)
A17: 서울 | B17: 반독점수사국 | C17: 반독점수사1과, 반독점수사2과, 반독점수사3과, 반독점수사4과 | D17: 3급 | E17: 4 | F17: 12 | G17: 28 | H17: 32 | I17: 28 | J17: 12 | K17: =SUM(E17:J17) | L17: 1
A18: 서울 | B18: 반부패수사국 | C18: 반부패수사1과, 반부패수사2과, 반부패수사3과, 공공안전수사과, 사회약자범죄특별수사과 | D18: 3급 | E18: 4 | F18: 23 | G18: 38 | H18: 43 | I18: 26 | J18: 14 | K18: =SUM(E18:J18) | L18: 1
A19: 서울 | B19: 마약수사국 | C19: 마약수사1과, 마약수사2과, 마약수사3과, 마약수사4과 | D19: 3급 | E19: 4 | F19: 18 | G19: 29 | H19: 33 | I19: 20 | J19: 12 | K19: =SUM(E19:J19) | L19: 1
A20: 서울 | B20: 첨단수사국 | C20: 방위사업·산업기술수사과, 사이버정보수사과, 보이스피싱범죄합동수사과 | D20: 3급 | E20: 3 | F20: 13 | G20: 19 | H20: 20 | I20: 11 | J20: 10 | K20: =SUM(E20:J20) | L20: 1 | M20: 방위사업·산업기술수사과: 전산·방송통신 6급(2)·7급(3)·8급(3)·9급(2) / 사이버정보수사과: 전산·방송통신 6급(1)·7급(2)·8급(2)·9급(1)
A21: 수원 | B21: 부속실 | C21: 수원지방중대범죄수사청장, 차장 | E21: 0 | F21: 0 | G21: 1 | H21: 0 | I21: 0 | J21: 0 | K21: =SUM(E21:J21) | L21: 2 | N21: 청장·차장 부속
A22: 수원 | B22: 담당관(4개) | C22: 수사심의담당관, 인권보호담당관, 기획공보담당관, 수사정보담당관 | D22: 4급 | E22: 0 | F22: 5 | G22: 10 | H22: 10 | I22: 4 | J22: 3 | K22: =SUM(E22:J22) | L22: 0 | N22: 담당관 4개 합계
A23: 수원 | B23: 경제범죄수사국 | C23: 중대경제범죄수사과, 금융범죄수사과, 반독점수사과, 범죄수익수사과 | D23: 3급 | E23: 3 | F23: 11 | G23: 22 | H23: 22 | I23: 17 | J23: 8 | K23: =SUM(E23:J23) | L23: 1
A24: 수원 | B24: 반부패수사국 | C24: 반부패수사1과, 반부패수사2과, 마약합동수사과, 방위사업·산업기술수사과 | D24: 3급 | E24: 3 | F24: 17 | G24: 27 | H24: 28 | I24: 18 | J24: 14 | K24: =SUM(E24:J24) | L24: 1
A25: 수원 | B25: 사무국 | C25: 총무과, 사건과, 수사지원과, 과학수사지원과 | D25: 3급 | E25: 0 | F25: 5 | G25: 9 | H25: 14 | I25: 14 | J25: 10 | K25: =SUM(E25:J25) | L25: 1 | M25: 총무과: 전산·방송통신 7급(1)·8급(1) / 시설 7급(1)·8급(1)·9급(1) / 운전 8급(2)·9급(4) / 방호 8급(2)·9급(2) / 기록연구사(1)
A26: 대전 | B26: 부속실 | C26: 대전지방중대범죄수사청장, 차장 | E26: 0 | F26: 0 | G26: 1 | H26: 0 | I26: 0 | J26: 0 | K26: =SUM(E26:J26) | L26: 2 | N26: 청장·차장 부속
A27: 대전 | B27: 담당관(4개) | C27: 수사심의담당관, 인권보호담당관, 기획공보담당관, 수사정보담당관 | D27: 4급 | E27: 0 | F27: 4 | G27: 8 | H27: 7 | I27: 4 | J27: 3 | K27: =SUM(E27:J27) | L27: 0 | N27: 담당관 4개 합계
A28: 대전 | B28: 경제범죄수사국 | C28: 중대경제범죄수사과, 금융범죄수사과, 국가재정범죄합동수사과, 범죄수익수사과 | D28: 3급 | E28: 6 | F28: 8 | G28: 15 | H28: 17 | I28: 7 | J28: 9 | K28: =SUM(E28:J28) | L28: 1
A29: 대전 | B29: 반부패수사국 | C29: 반부패수사1과, 반부패수사2과, 마약수사과, 산업기술수사과 | D29: 3급 | E29: 4 | F29: 12 | G29: 20 | H29: 24 | I29: 11 | J29: 6 | K29: =SUM(E29:J29) | L29: 1 | M29: 산업기술수사과: 전산·방송통신 6급(1)·7급(1)·9급(1)
A30: 대전 | B30: 사무국 | C30: 총무과, 사건과, 수사지원과, 과학수사지원과 | D30: 3급 | E30: 0 | F30: 5 | G30: 8 | H30: 11 | I30: 11 | J30: 9 | K30: =SUM(E30:J30) | L30: 1 | M30: 총무과: 전산·방송통신 7급(1)·8급(1) / 시설 7급(1)·8급(1)·9급(1) / 운전 8급(1)·9급(5) / 방호 8급(2)·9급(2) / 기록연구사(1) · 과학수사지원과: 전산·방송통신 6급(1)
A31: 대구 | B31: 부속실 | C31: 대구지방중대범죄수사청장, 차장 | E31: 0 | F31: 0 | G31: 1 | H31: 0 | I31: 0 | J31: 0 | K31: =SUM(E31:J31) | L31: 2 | N31: 청장·차장 부속
A32: 대구 | B32: 담당관(4개) | C32: 수사심의담당관, 인권보호담당관, 기획공보담당관, 수사정보담당관 | D32: 4급 | E32: 0 | F32: 5 | G32: 8 | H32: 7 | I32: 4 | J32: 3 | K32: =SUM(E32:J32) | L32: 0 | N32: 담당관 4개 합계
A33: 대구 | B33: 경제범죄수사국 | C33: 중대경제범죄수사과, 금융범죄수사과, 범죄수익수사과 | D33: 3급 | E33: 2 | F33: 7 | G33: 12 | H33: 14 | I33: 6 | J33: 5 | K33: =SUM(E33:J33) | L33: 1
A34: 대구 | B34: 반부패수사국 | C34: 반부패수사1과, 반부패수사2과, 마약수사과 | D34: 3급 | E34: 4 | F34: 8 | G34: 17 | H34: 20 | I34: 10 | J34: 5 | K34: =SUM(E34:J34) | L34: 1
A35: 대구 | B35: 사무국 | C35: 총무과, 사건과, 수사지원과, 과학수사지원과 | D35: 3급 | E35: 0 | F35: 4 | G35: 8 | H35: 12 | I35: 11 | J35: 9 | K35: =SUM(E35:J35) | L35: 1 | M35: 총무과: 전산·방송통신 7급(1)·8급(1) / 시설 7급(1)·8급(1)·9급(1) / 운전 8급(1)·9급(5) / 방호 8급(2)·9급(2) / 기록연구사(1) · 과학수사지원과: 전산·방송통신 9급(1)
A36: 부산 | B36: 부속실 | C36: 부산지방중대범죄수사청장, 차장 | E36: 0 | F36: 0 | G36: 1 | H36: 0 | I36: 0 | J36: 0 | K36: =SUM(E36:J36) | L36: 2 | N36: 청장·차장 부속
A37: 부산 | B37: 담당관(4개) | C37: 수사심의담당관, 인권보호담당관, 기획공보담당관, 수사정보담당관 | D37: 4급 | E37: 0 | F37: 5 | G37: 10 | H37: 8 | I37: 4 | J37: 3 | K37: =SUM(E37:J37) | L37: 0 | N37: 담당관 4개 합계
A38: 부산 | B38: 경제범죄수사국 | C38: 중대경제범죄수사과, 국제경제범죄수사과, 금융범죄수사과, 범죄수익수사과 | D38: 3급 | E38: 3 | F38: 13 | G38: 20 | H38: 26 | I38: 15 | J38: 5 | K38: =SUM(E38:J38) | L38: 1
A39: 부산 | B39: 반부패수사국 | C39: 반부패수사1과, 반부패수사2과, 마약수사1과, 마약수사2과 | D39: 3급 | E39: 3 | F39: 16 | G39: 25 | H39: 31 | I39: 19 | J39: 12 | K39: =SUM(E39:J39) | L39: 1
A40: 부산 | B40: 사무국 | C40: 총무과, 사건과, 수사지원과, 과학수사지원과 | D40: 3급 | E40: 0 | F40: 5 | G40: 11 | H40: 15 | I40: 13 | J40: 13 | K40: =SUM(E40:J40) | L40: 1 | M40: 총무과: 전산·방송통신 7급(1)·8급(1) / 시설 7급(1)·8급(1)·9급(1) / 운전 8급(2)·9급(4) / 방호 8급(2)·9급(2) / 기록연구사(1) · 과학수사지원과: 전산·방송통신 9급(1), 보건연구관(1), 보건연구사(2)
...

Sheet 조직·업무
A1: 청 | B1: 구분 | C1: 상위 부서 | D1: 부서 | E1: 보직 계급 | F1: 근거 조문 | G1: 분장 업무 | H1: 사건 범위 | I1: 일반직 | J1: 비고
A2: 본청 | B2: 지휘부 | D2: 중대범죄수사청장 | E2: 정무직 | F2: 법 §7 · 직제 §3 | G2: 1. 중수청의 사무를 총괄하고 직원을 지휘·감독 (법 §7②) 2. 중대범죄등에 대한 수사관의 수사와 법률에 따라 중수청 권한에 속하는 사항 관장 (직제 §3) 3. 후보추천위원회 추천 → 행안부장관 제청 → 국회 인사청문 → 대통령 임명, 임기 2년·중임 불가 (법 §7③④)
A3: 본청 | B3: 지휘부 | C3: 중대범죄수사청장 | D3: 차장 | E3: 1급 | F3: 법 §10 · 직제 §6 | G3: 1. 청장을 보좌하고, 청장이 부득이한 사유로 직무를 수행할 수 없을 때 직무 대리 (법 §10②) 2. 기획조정관·인사정책기획관·수사정보관의 보좌를 받음 (직제 §5③)
A4: 본청 | B4: 청장 직속 보좌기관 | D4: 감찰관 | E4: 2급 | F4: 직제 §7 | G4: 1. 소속 공무원의 비위 조사 2. 비위 정보수집·관리, 진정 등 내사사건 조사·처리 3. 감찰 법령·제도·정책 검토·연구·개선 4. 사무감사·기강감사 및 사건평정 5. 감사제도 운영 및 감사계획 수립·조정 6. 인권정책 총괄, 범죄피해자 보호·지원, 인권침해 감독·예방 7. 양성평등 정책 및 성희롱·성폭력 예방 8. 법 §44 수사심의 제도, 법 §47 손실보상 제도 운영 9. 퇴직공직자 취업 제한 10. 병역사항 신고 및 재산등록 | I4: 인권·양성평등담당관: 전문경력관 나급(1) | J4: 감찰관은 법 §26에 따라 내부·외부 공개모집으로 임용합니다(임기 2년, 연임 불가).
A5: 본청 | B5: 청장 직속 보좌기관 | C5: 감찰관 | D5: 감찰담당관 | E5: 3급 | F5: 시행규칙 §2② | G5: 1. 소속 공무원의 비위 조사 2. 비위 정보수집·관리 및 진정, 내사사건 조사·처리 3. 감찰 법령·제도·정책 검토·연구·개선 4. 퇴직공직자의 취업 제한 5. 병역사항 신고 및 재산등록 6. 청장이 감찰에 관하여 지시한 사항 7. 관 내 다른 담당관 주관에 속하지 않는 사항
A6: 본청 | B6: 청장 직속 보좌기관 | C6: 감찰관 | D6: 감사담당관 | E6: 4급 | F6: 시행규칙 §2③ | G6: 1. 사무감사·기강감사 및 사건평정 2. 감사제도 운영 및 감사계획 수립·조정 3. 청장이 감사에 관하여 지시한 사항
A7: 본청 | B7: 청장 직속 보좌기관 | C7: 감찰관 | D7: 인권·양성평등담당관 | E7: 4급 | F7: 시행규칙 §2④ | G7: 1. 인권업무 기획·법령·제도·정책 총괄·검토·연구·개선 2. 인권침해 예방·감독 및 사건 처리 3. 범죄피해자 보호·지원 4. 양성평등 정책 및 성희롱·성폭력 예방 5. 양성평등 침해 및 성희롱·성폭력 사건 처리 6. 인권·양성평등 유관기관 교류·협력 7. 법 §44 수사심의 제도 수립·운영 8. 법 §47 손실보상 제도 수립·운영
A8: 본청 | B8: 청장 직속 보좌기관 | D8: 대변인 | E8: 2급 | F8: 직제 §8 | G8: 1. 주요정책 대국민 홍보 계획 수립·조정 및 협의·지원 2. 청 내 업무의 대외 정책 발표 3. 보도자료 관리·분석, 오보·왜곡보도 대응 4. 언론취재 지원 및 협조 5. 온라인대변인 지정·운영 등 소셜 미디어 정책소통 총괄 | I8: 공보담당관: 전문경력관 나급(1)
A9: 본청 | B9: 청장 직속 보좌기관 | C9: 대변인 | D9: 공보담당관 | E9: 4급 | F9: 시행규칙 §3 | G9: 1. 주요정책 대국민 홍보 계획 수립·조정 및 협의·지원 2. 청 내 업무의 대외 정책 발표 3. 보도자료 관리·분석, 오보·왜곡보도 대응 4. 언론취재 지원 및 협조 5. 중수청 업무 관련 각종 상황관리 및 공보사무
A10: 본청 | B10: 차장 보좌기관 | D10: 기획조정관 | E10: 2급 | F10: 직제 §9 | G10: 1. 주요정책·업무계획 수립·총괄·조정 2. 대국회 업무 총괄·조정 3. 예산 편성·집행·조정 4. 정부업무평가 및 성과관리 5. 행정개선 총괄 6. 국정과제 발굴·점검 7. 행정심판·소송·민원·국민신문고·정보공개 8. 국제협력 정책 및 국제수사공조 9. 정보화계획, 정보보안·개인정보보호 10. 형사사법정보시스템(KICS) 운영·관리 11. 비상대비, 정부비상훈련·직장예비군, 재난·위기 연계체계 | I10: 정보통신담당관: 전산·방송통신 5급(2)·6급(4)·7급(4)·8급(2)·9급(1) / 비상안전담당관실: 방호 8급(3)·9급(4)
A11: 본청 | B11: 차장 보좌기관 | C11: 기획조정관 | D11: 기획재정담당관 | E11: 3급 | F11: 시행규칙 §4② | G11: 1. 주요정책·업무계획 수립·종합·조정 2. 주요사업 진행 파악 및 심사평가 3. 대국회 업무 총괄·조정 4. 성과관리 기본계획·전략계획·시행계획 수립 5. 행정개선 총괄 및 지원 6. 정부업무평가 총괄·조정 7. 국정과제 발굴·선정·점검 8. 소관 법령 및 행정규칙 총괄·조정 9. 예산 편성·결산 총괄 및 집행 조정 10. 민원, 국민신문고 및 정보공개 11. 행정심판 및 소송사무 12. 관 내 다른 담당관 주관에 속하지 않는 사항
A12: 본청 | B12: 차장 보좌기관 | C12: 기획조정관 | D12: 국제협력담당관 | E12: 4급 | F12: 시행규칙 §4③ | G12: 1. 국제협력 정책 수립·총괄·조정 2. 국제수사공조 등 국제협력 업무 3. 중대범죄등 수사 관련 외국기관·국제기구 협력 및 국제회의 4. 국제형사사법 정보·자료의 조사·수집·연구·간행 5. 그 밖의 수사 분야 국제협력
A13: 본청 | B13: 차장 보좌기관 | C13: 기획조정관 | D13: 정보통신담당관 | E13: 4급 | F13: 시행규칙 §4④ | G13: 1. 정보화계획 수립·추진 2. 전산업무 개발·운영 3. 통신 및 보안 4. 개인정보보호 5. 전산장비·자료 및 통신기기 운영·관리 6. 형사사법정보시스템(KICS) 운영·관리 7. 공공데이터 제공 및 이용 활성화 8. 데이터기반행정 활성화 9. 그 밖의 정보화
A14: 본청 | B14: 차장 보좌기관 | C14: 기획조정관 | D14: 비상안전담당관 | E14: 임기제 4급 | F14: 시행규칙 §4⑤ · §38② | G14: 1. 국가비상사태 대비 제반계획 수립 및 훈련 총괄 2. 정부비상훈련, 직장예비군 및 민방위대 관리 3. 안전관리·재난·위기상황 관리기관과의 연계체계 구축·운영 | J14: 비상안전담당관은 「비상대비에 관한 법률」 §12의2에 따라 추후 모집 예정(공고 별첨1).
A15: 본청 | B15: 차장 보좌기관 | D15: 인사정책기획관 | E15: 2급 | F15: 직제 §10 | G15: 1. 소속 공무원 인사계획 수립 및 인사 운영 2. 채용·승진·전보 등 임용 3. 교육, 상훈, 징계, 근무평정, 성과상여금 4. 조직진단·평가를 통한 조직·정원 관리 5. 수사정책 기획·조정 6. 수사업무 법령·제도·정책 연구·관리 7. 수사·조사 지원 8. 수사업무 유관기관 교류·협력 | I15: 인사담당관: 전산·방송통신 7급(1)·8급(2)
A16: 본청 | B16: 차장 보좌기관 | C16: 인사정책기획관 | D16: 인사담당관 | E16: 3급 | F16: 시행규칙 §5② | G16: 1. 소속 공무원 인사계획 수립 및 인사 운영 2. 채용·승진·전보 등 임용 3. 상훈, 징계, 근무평정 및 성과상여금 4. 조직진단·평가를 통한 조직·정원 관리 5. 교육훈련 계획 수립·운영 및 제도개선 6. 인사 제도 및 통계 관리 등 인사 사무 7. 관 내 다른 담당관 주관에 속하지 않는 사항
A17: 본청 | B17: 차장 보좌기관 | C17: 인사정책기획관 | D17: 수사정책담당관 | E17: 3급 | F17: 시행규칙 §5③ | G17: 1. 수사정책 기획 및 조정 2. 수사업무 관련 법령·제도·정책 연구 및 관리 3. 중대범죄등 수사업무에 대한 수사·조사 지원 4. 수사업무 유관기관 교류·협력 5. 수사정책 관련 제도·정책 연구 및 운영
A18: 본청 | B18: 차장 보좌기관 | D18: 수사정보관 | E18: 2급 | F18: 직제 §11 | G18: 1. 중수청 직무 관련 정보·자료의 수집·분석·검증·평가·관리 2. 지방청이 수집한 중대범죄등 정보·자료의 분석·검증·평가·관리 3. 다른 기관에서 이첩된 정보·자료의 분석·검증·평가·관리 4. 중대범죄등 정보 관련 기획·조정·지원·지휘·감독 및 교육
A19: 본청 | B19: 차장 보좌기관 | C19: 수사정보관 | D19: 수사정보1담당관 | E19: 3급 | F19: 시행규칙 §6② | G19: 1. 중수청 직무 범죄 관련 정보·자료의 분석·검증·평가·관리 2. 지방청 수집 정보·자료의 분석·검증·평가·관리 3. 다른 기관 이첩 정보·자료의 분석·검증·평가·관리 4. 그 밖의 중요 정보·자료의 분석·검증·평가·관리 5. 중대범죄등 정보 사무의 기획·조정·지원·지휘·감독 및 교육 6. 관 내 다른 담당관 주관에 속하지 않는 사항
A20: 본청 | B20: 차장 보좌기관 | C20: 수사정보관 | D20: 수사정보2담당관 | E20: 4급 | F20: 시행규칙 §6③ | G20: 1. 중수청 직무 범죄 관련 정보·자료의 수집 및 관리 2. 그 밖의 중요 정보·자료의 수집 및 관리
A21: 본청 | B21: 수사 부서 (지방청 지휘·감독) | D21: 경제범죄수사국 | E21: 2급 | F21: 직제 §13 | G21: 1. 아래 사건 및 이와 직접 관련이 있어 중대범죄수사청장이 명하는 사건에 관한 지방청 사무의 지휘·감독 2. 지방청 사무의 보고 및 관련 정보의 보고 3. 진정·내사·탄원 등의 접수·처리 4. 범죄 현상·정보의 수집·분석·관리·연구, 정책·수사지침 수립 5. 수사기법 개발·지원 및 교육, 통계·기록물 관리 6. 관련 기관 협조 | H21: - 경제·금융·공정거래·기업·조세·가상자산·보이스피싱·재산국외도피·범죄수익은닉범죄사건 및 청장이 명하는 관련 사건 - 범죄수익추적·환수 지원
A22: 본청 | B22: 수사 부서 (지방청 지휘·감독) | C22: 경제범죄수사국 | D22: 경제범죄수사과 | E22: 3급 | F22: 시행규칙 §7② | G22: 1. 아래 사건 및 이와 직접 관련이 있어 중대범죄수사청장이 명하는 사건에 관한 지방청 사무의 지휘·감독 2. 지방청 사무의 보고 및 관련 정보의 보고 3. 진정·내사·탄원 등의 접수·처리 4. 범죄 현상·정보의 수집·분석·관리·연구, 정책·수사지침 수립 5. 수사기법 개발·지원 및 교육, 통계·기록물 관리 6. 관련 기관 협조 7. 그 밖에 국 내 다른 과의 주관에 속하지 않는 사항 | H22: - 「형법」 제2편 제39장(사기·공갈)·제40장(횡령·배임)의 범죄 - 「특정범죄 가중처벌 등에 관한 법률」 제6조·제8조·제8조의2 - 「특정경제범죄 가중처벌 등에 관한 법률」 제3조, 제5조~제9조 - 「전기통신금융사기 피해 방지 및 피해자산 환급에 관한 특별법」·「전자금융거래법」 위반 - 「형법」 제114조의 범죄 - 법 제2조제2호나목 사건 중 경제·조세·보이스피싱범죄
A23: 본청 | B23: 수사 부서 (지방청 지휘·감독) | C23: 경제범죄수사국 | D23: 금융범죄수사과 | E23: 4급 | F23: 시행규칙 §7③ | G23: 1. 아래 사건 및 이와 직접 관련이 있어 중대범죄수사청장이 명하는 사건에 관한 지방청 사무의 지휘·감독 2. 지방청 사무의 보고 및 관련 정보의 보고 3. 진정·내사·탄원 등의 접수·처리 4. 범죄 현상·정보의 수집·분석·관리·연구, 정책·수사지침 수립 5. 수사기법 개발·지원 및 교육, 통계·기록물 관리 6. 관련 기관 협조 | H23: - 「자본시장과 금융투자업에 관한 법률」 위반 - 「가상자산 이용자 보호 등에 관한 법률」 위반 - 법 제2조제2호나목 사건 중 금융·가상자산범죄
A24: 본청 | B24: 수사 부서 (지방청 지휘·감독) | C24: 경제범죄수사국 | D24: 반독점수사과 | E24: 4급 | F24: 시행규칙 §7④ | G24: 1. 아래 사건 및 이와 직접 관련이 있어 중대범죄수사청장이 명하는 사건에 관한 지방청 사무의 지휘·감독 2. 지방청 사무의 보고 및 관련 정보의 보고 3. 진정·내사·탄원 등의 접수·처리 4. 범죄 현상·정보의 수집·분석·관리·연구, 정책·수사지침 수립 5. 수사기법 개발·지원 및 교육, 통계·기록물 관리 6. 관련 기관 협조 | H24: - 「독점규제 및 공정거래에 관한 법률」 제124조·제125조 - 법 제2조제2호나목 사건 중 공정거래·기업범죄
A25: 본청 | B25: 수사 부서 (지방청 지휘·감독) | C25: 경제범죄수사국 | D25: 범죄수익수사과 | E25: 4급 | F25: 시행규칙 §7⑤ | G25: 1. 아래 사건 및 이와 직접 관련이 있어 중대범죄수사청장이 명하는 사건에 관한 지방청 사무의 지휘·감독 2. 지방청 사무의 보고 및 관련 정보의 보고 3. 진정·내사·탄원 등의 접수·처리 4. 범죄 현상·정보의 수집·분석·관리·연구, 정책·수사지침 수립 5. 수사기법 개발·지원 및 교육, 통계·기록물 관리 6. 관련 기관 협조 | H25: - 「특정경제범죄 가중처벌 등에 관한 법률」 제4조(재산국외도피) - 법 제2조제1호바목(범죄수익은닉규제법 제3조·제4조) 범죄 - 법 제2조제2호나목 사건 중 재산국외도피·범죄수익은닉범죄 - 범죄수익의 추적 및 환수 지원
A26: 본청 | B26: 수사 부서 (지방청 지휘·감독) | D26: 반부패수사국 | E26: 2급 | F26: 직제 §14 | G26: 1. 아래 사건 및 이와 직접 관련이 있어 중대범죄수사청장이 명하는 사건에 관한 지방청 사무의 지휘·감독 2. 지방청 사무의 보고 및 관련 정보의 보고 3. 진정·내사·탄원 등의 접수·처리 4. 범죄 현상·정보의 수집·분석·관리·연구, 정책·수사지침 수립 5. 수사기법 개발·지원 및 교육, 통계·기록물 관리 6. 관련 기관 협조 | H26: - 부패범죄, 공소청·공수처·법원·경찰 등 공무원 범죄, 마약류·공공안전·정치자금·방위사업·군사기밀범죄사건 - 「형사소송법」 §197의2⑧ 보완수사 요구 사건, §245의8⑨ 재수사 요구 사건 - 자금추적·회계분석 지원
A27: 본청 | B27: 수사 부서 (지방청 지휘·감독) | C27: 반부패수사국 | D27: 반부패수사과 | E27: 3급 | F27: 시행규칙 §8② | G27: 1. 아래 사건 및 이와 직접 관련이 있어 중대범죄수사청장이 명하는 사건에 관한 지방청 사무의 지휘·감독 2. 지방청 사무의 보고 및 관련 정보의 보고 3. 진정·내사·탄원 등의 접수·처리 4. 범죄 현상·정보의 수집·분석·관리·연구, 정책·수사지침 수립 5. 수사기법 개발·지원 및 교육, 통계·기록물 관리 6. 관련 기관 협조 7. 그 밖에 국 내 다른 과의 주관에 속하지 않는 사항 | H27: - 「형법」 제122조, 제124조~제127조, 제129조~제133조, 제141조, 제225조·제227조·제227조의2 및 제229조(행사죄) - 「변호사법」 제111조 - 「특정범죄 가중처벌 등에 관한 법률」 제2조~제5조 - 「형법」 제123조의2 - 공소청·경찰·공수처·법원 소속 공무원이 재직 중 저지른 범죄(퇴직자 포함) - 법 제2조제2호나목 사건 중 부패범죄·공무원 범죄
A28: 본청 | B28: 수사 부서 (지방청 지휘·감독) | C28: 반부패수사국 | D28: 마약수사과 | E28: 4급 | F28: 시행규칙 §8③ | G28: 1. 아래 사건 및 이와 직접 관련이 있어 중대범죄수사청장이 명하는 사건에 관한 지방청 사무의 지휘·감독 2. 지방청 사무의 보고 및 관련 정보의 보고 3. 진정·내사·탄원 등의 접수·처리 4. 범죄 현상·정보의 수집·분석·관리·연구, 정책·수사지침 수립 5. 수사기법 개발·지원 및 교육, 통계·기록물 관리 6. 관련 기관 협조 | H28: - 「마약류 관리에 관한 법률」 위반 - 「특정범죄 가중처벌 등에 관한 법률」 제11조 - 법 제2조제2호나목 사건 중 마약류 범죄
A29: 본청 | B29: 수사 부서 (지방청 지휘·감독) | C29: 반부패수사국 | D29: 공공사회안전수사과 | E29: 4급 | F29: 시행규칙 §8④ | G29: 1. 아래 사건 및 이와 직접 관련이 있어 중대범죄수사청장이 명하는 사건에 관한 지방청 사무의 지휘·감독 2. 지방청 사무의 보고 및 관련 정보의 보고 3. 진정·내사·탄원 등의 접수·처리 4. 범죄 현상·정보의 수집·분석·관리·연구, 정책·수사지침 수립 5. 수사기법 개발·지원 및 교육, 통계·기록물 관리 6. 관련 기관 협조 | H29: - 「형법」 제2편 제1장(내란)·제2장(외환)의 죄, 제128조 - 「정치자금법」 제45조 - 「국가정보원법」 제21조·제22조 - 「국회에서의 증언·감정 등에 관한 법률」 제14조제1항 - 「방위산업기술 보호법」·「군사기밀 보호법」 위반 - 「형사소송법」 제197조의2제8항 보완수사 요구 사건 - 「형사소송법」 제245조의8제9항 재수사 요구 사건 - 법 제2조제2호나목 사건 중 공공안전·정치자금·방산·군사기밀·국회위증 범죄 | I29: 심리연구사(2)
A30: 본청 | B30: 수사 부서 (지방청 지휘·감독) | C30: 반부패수사국 | D30: 자금추적·회계분석과 | E30: 4급 | F30: 시행규칙 §8⑤ | G30: 1. 자금추적·회계분석 지원 및 그 사무에 관한 지방청 사무의 지휘·감독 2. 지방청 사무의 보고 및 관련 정보 보고 3. 진정·내사·탄원 등의 접수·처리 4. 정보 수집·분석·관리·연구, 정책·수사지침 수립 5. 기법 개발·지원 및 교육, 통계·기록물 관리 6. 관련 기관 협조 7. 수사장비 확보·개발 및 운영 | H30: - 중대범죄수사청장이 명하는 사건의 자금추적·회계분석 지원
A31: 본청 | B31: 수사 부서 (지방청 지휘·감독) | D31: 과학수사국 | E31: 2급 | F31: 직제 §15 | G31: 1. 아래 사건 및 이와 직접 관련이 있어 중대범죄수사청장이 명하는 사건에 관한 지방청 사무의 지휘·감독 2. 지방청 사무의 보고 및 관련 정보의 보고 3. 진정·내사·탄원 등의 접수·처리 4. 범죄 현상·정보의 수집·분석·관리·연구, 정책·수사지침 수립 5. 수사기법 개발·지원 및 교육, 통계·기록물 관리 6. 관련 기관 협조 | H31: - 사이버·산업기술범죄사건 및 청장이 명하는 관련 사건 - 전자적 증거·AI가상자산 분석·지원
A32: 본청 | B32: 수사 부서 (지방청 지휘·감독) | C32: 과학수사국 | D32: 사이버기술수사과 | E32: 3급 | F32: 시행규칙 §9② | G32: 1. 아래 사건 및 이와 직접 관련이 있어 중대범죄수사청장이 명하는 사건에 관한 지방청 사무의 지휘·감독 2. 지방청 사무의 보고 및 관련 정보의 보고 3. 진정·내사·탄원 등의 접수·처리 4. 범죄 현상·정보의 수집·분석·관리·연구, 정책·수사지침 수립 5. 수사기법 개발·지원 및 교육, 통계·기록물 관리 6. 관련 기관 협조 7. 수사지원을 위한 국제수사공조 등 이행·지원 8. 수사장비 확보·개발 및 운영 9. 과학수사업무 기획·종합계획 수립 및 과학수사 행정 10. 관련 지도·교육 11. 그 밖에 국 내 다른 과의 주관에 속하지 않는 사항 | H32: - 「산업기술의 유출방지 및 보호에 관한 법률」 제36조~제38조, 「부정경쟁방지 및 영업비밀보호에 관한 법률」 제18조~제18조의4 - 정보통신망법 제71조제1항제11호~제14호·제2항, 형법 제356조, 특경법 제3조 중 기술유출 등 국가핵심기반 공격 사이버범죄 - 법 제2조제2호나목 사건 중 사이버·산업기술범죄 | I32: 전산·방송통신 5급(1)·6급(1)·7급(4)·9급(1)
A33: 본청 | B33: 수사 부서 (지방청 지휘·감독) | C33: 과학수사국 | D33: 디지털수사과 | E33: 4급 | F33: 시행규칙 §9③ | G33: 1. 전자적 증거의 분석 2. 전자적 증거 분석기법 연구·개발 3. 전자적 과학수사기법 연구·개발 4. 디지털수사 유관기관 협조 5. 디지털수사 장비 확보·개발·운영 6. 관련 지도·교육 | I33: 전산·방송통신 5급(1)·6급(1)·8급(2)
A34: 본청 | B34: 수사 부서 (지방청 지휘·감독) | C34: 과학수사국 | D34: AI가상자산분석과 | E34: 4급 | F34: 시행규칙 §9④ | G34: 1. AI 활용 범죄 및 가상자산 추적·분석 2. AI 활용 범죄 및 수사기법 연구·개발 3. 가상자산 추적·분석기법 연구·개발 4. 관련 기관 협조 5. AI가상자산분석 장비 확보·개발·운영 6. 관련 지도·교육
A35: 본청 | B35: 수사 부서 (지방청 지휘·감독) | D35: 운영지원과 | E35: 4급 | F35: 직제 §12 | G35: 1. 보안 및 청사관리 2. 관인 및 관인대장 관리 3. 문서 접수·발송·보존·관리 및 기록관 운영 4. 소속 공무원 복무·연금·급여 및 복리후생 5. 예산운영·회계 및 결산 6. 물품구매·조달 및 물품관리 7. 중대산업재해 관련 안전·보건 8. 소속 공무원 역량 개발 9. 차량 유지·운영 10. 그 밖에 청 내 다른 부서 주관에 속하지 않는 사항 | I35: 시설·공업 7급(2) / 운전 7급(1)·8급(3)·9급(4) / 기록연구사(1)
A36: 서울 | B36: 지휘부 | D36: 서울지방중대범죄수사청장 | E36: 1급 | F36: 직제 §20 | G36: 1. 지방청의 사무를 맡아 처리하고 소속 직원을 지휘·감독 (법 §11②) 2. 중수청 소관사무를 관할구역별로 분장하여 수행 (직제 §18)
A37: 서울 | B37: 지휘부 | C37: 서울지방중대범죄수사청장 | D37: 1차장 | E37: 2급 | F37: 직제 §23② | G37: 1. 경제범죄수사국·금융범죄수사국 소관업무에 관하여 청장 보좌 2. 청장 직무대리 1순위 (직제 §23①)
A38: 서울 | B38: 지휘부 | C38: 서울지방중대범죄수사청장 | D38: 2차장 | E38: 2급 | F38: 직제 §23③ | G38: 1. 반독점수사국·반부패수사국 소관업무에 관하여 청장 보좌 2. 청장 직무대리 2순위
A39: 서울 | B39: 지휘부 | C39: 서울지방중대범죄수사청장 | D39: 3차장 | E39: 2급 | F39: 직제 §23④ | G39: 1. 마약수사국·첨단수사국 소관업무에 관하여 청장 보좌 2. 청장 직무대리 3순위 | J39: 공고 별첨1 직위표는 3차장이 첨단수사국과 사무국 업무를 총괄한다고 적고 있습니다.
A40: 서울 | B40: 청장 밑 담당관 | D40: 수사심의담당관 | E40: 4급 | F40: 시행규칙 §11 | G40: 1. 법 제44조에 따른 수사심의 2. 구체적 사건 수사의 지휘·감독 적법성·정당성에 대한 이의제기 심의 3. 법 제47조에 따른 손실보상 4. 소송사무
...

Sheet 관할구역
A1: 청 | B1: 기관명 | C1: 위치(공고 기준) | D1: 관할구역 | E1: 확인 필요
A2: 본청 | B2: 중대범죄수사청 | C2: 서울 중구 수표동 35-10, 르네스퀘어 | D2: 전국 (지방청 사무의 지휘·감독) | E2: —
A3: 서울 | B3: 서울지방중대범죄수사청 | C3: 서울 중구 수표동 35-10, 르네스퀘어 | D3: 서울특별시, 인천광역시, 경기도 북부 (의정부지방법원 관할 지역), 강원특별자치도 | E3: 직제 별표 1 원문 대조
A4: 수원 | B4: 수원지방중대범죄수사청 | C4: 경기 수원시 영통구 도청로 52, 경기신용보증재단 사옥 | D4: 경기도 남부 (수원지방법원 관할 지역) | E4: 직제 별표 1 원문 대조
A5: 대전 | B5: 대전지방중대범죄수사청 | C5: 세종특별자치시 소재 | D5: 대전광역시, 세종특별자치시, 충청남도, 충청북도 | E5: 직제 별표 1 원문 대조
A6: 대구 | B6: 대구지방중대범죄수사청 | C6: 대구 남구 대명동 1795-3, 남산빌딩 | D6: 대구광역시, 경상북도 | E6: 직제 별표 1 원문 대조
A7: 부산 | B7: 부산지방중대범죄수사청 | C7: 부산 강서구 명지동 3595-2, 퍼스트월드 브라이튼 | D7: 부산광역시, 울산광역시, 경상남도 | E7: 직제 별표 1 원문 대조
A8: 광주 | B8: 광주지방중대범죄수사청 | C8: 전남광주통합특별시 북구 중흥동 712-3, 한경빌딩 | D8: 전남광주통합특별시, 전북특별자치도, 제주특별자치도 | E8: 직제 별표 1 원문 대조
A10: 관할구역은 직제 §19·별표 1이 정합니다. 업로드 자료에 별표가 없어 ‘각 고등법원 관할구역에 대응해 설치’ 원칙으로 정리했습니다. 청사 위치는 임대차 계약에 따라 바뀔 수 있습니다(공고 2.).

Sheet 법령 목록
A1: 분류 | B1: 법령명 | C1: 중요도 | D1: 확인할 내용 | E1: 국가법령정보센터 | F1: 확인(○) | G1: 메모
A2: 중수청 조직·운영 | B2: 중대범죄수사청 조직 및 운영에 관한 법률 | C2: 필수 | D2: 직무 범위(§2·§4), 인사(§16~§40), 직무수행(§41~§49), 벌칙 | E2: 검색 열기 ↗
A3: 중수청 조직·운영 | B3: 중대범죄수사청 조직 및 운영에 관한 법률 시행령 | C3: 필수 | D3: 직접관련 범죄, 이의제기, 인지 통보·이첩, 수사심의, 손실보상 | E3: 검색 열기 ↗
A4: 중수청 조직·운영 | B4: 중대범죄수사청과 그 소속기관 직제 | C4: 필수 | D4: 본청·지방청 하부조직, 관할구역(별표 1), 정원(별표 2·3) | E4: 검색 열기 ↗
A5: 중수청 조직·운영 | B5: 중대범죄수사청과 그 소속기관 직제 시행규칙 | C5: 필수 | D5: 과·담당관 사무분장, 직급별 정원(별표 1·2) | E5: 검색 열기 ↗
A6: 중수청 조직·운영 | B6: 중대범죄수사청수사관 임용령 | C6: 필수 | D6: 상당 계급, 임용권 위임, 시보·승진·전보 | E6: 검색 열기 ↗
A7: 중수청 조직·운영 | B7: 중대범죄수사청 개청준비단 설치 및 운영에 관한 규정 | C7: 참고 | D7: 국무총리훈령 제933호 · 개청 준비 경과 | E7: 검색 열기 ↗
A8: 인사·복무 | B8: 국가공무원법 | C8: 필수 | D8: 법 §40에 따라 일반직 규정 준용 · 결격(§33), 징계(제10장) | E8: 검색 열기 ↗
A9: 인사·복무 | B9: 공무원임용령 | C9: 업무 | D9: 준용되는 임용 일반 원칙 | E9: 검색 열기 ↗
A10: 인사·복무 | B10: 국가공무원 복무규정 | C10: 필수 | D10: 근무시간, 휴가, 겸직, 복장 | E10: 검색 열기 ↗
A11: 인사·복무 | B11: 공무원 징계령 | C11: 업무 | D11: 징계 절차 일반 | E11: 검색 열기 ↗
A12: 인사·복무 | B12: 공무원 행동강령 | C12: 필수 | D12: 이해충돌, 부정청탁, 금품 수수 | E12: 검색 열기 ↗
A13: 인사·복무 | B13: 공직자의 이해충돌 방지법 | C13: 업무 | D13: 사적이해관계 신고, 직무관련자 거래 | E13: 검색 열기 ↗
... A56: 개인정보·민원·정보공개 | B56: 범죄피해자 보호법 | C56: 업무 | D56: 피해자 보호·지원 | E56: 검색 열기 ↗
B58: 확인 진행률 | C58: =COUNTIF(F2:F56,"○")&" / "&COUNTA(B2:B56)
B59: 필수 법령 확인 | C59: =COUNTIFS(C2:C56,"필수",F2:F56,"○")&" / "&COUNTIF(C2:C56,"필수")

Sheet 내 보관함
A1: 이름 | B1: 분류 | C1: 관련 분야 | D1: 링크 | E1: 핵심 조문·메모 | F1: 등록일
A2: (예시) 검사와 사법경찰관의 상호협력과 일반적 수사준칙에 관한 규정 | B2: 대통령령 | C2: 형사절차 | D2: https://www.law.go.kr/lsSc.do?menuId=1&query=%EA%B2%80%EC%82%AC%EC%99%80%20%EC%82%AC%EB%B2%95%EA%B2%BD%EC%B0%B0%EA%B4%80%EC%9D%98%20%EC%83%81%ED%98%B8%ED%98%91%EB%A0%A5%EA%B3%BC%20%EC%9D%BC%EB%B0%98%EC%A0%81%20%EC%88%98%EC%82%AC%EC%A4%80%EC%B9%99%EC%97%90%20%EA%B4%80%ED%95%9C%20%EA%B7%9C%EC%A0%95 | E2: 공소청 체제에 맞춘 개정 여부 확인 필요. 보완수사 요구 관련 조문 표시. | F2: 2026-10-02

Sheet 타기관 충원
A1: 기관 | B1: 인원 | C1: 계급 구성
A2: 경찰청 | B2: 37 | C2: 경정 2, 경감 8, 경위 11, 경사 16
A3: 국세청 | B3: 8 | C3: 6급 1, 7급 5, 8급 2
A4: 관세청 | B4: 5 | C4: 6급 2, 7급 2, 8급 1
A5: 법무부 | B5: 3 | C5: 6급 1, 7급 2
A6: 해양경찰청 | B6: 2 | C6: 경사 1, 경장 1
A7: 금융위원회 | B7: 2 | C7: 5급 2
A8: 합계 | B8: =SUM(B2:B7)
A10: 근거: 「중대범죄수사청과 그 소속기관 직제」 §36④. 중수청장은 충원 방법·절차를 해당 기관장과 미리 협의합니다.
